Workbook

Sheet S0 Qualified Executions
A1: Record ID | B1: Cell ID | C1: Population | D1: Cohort Year | E1: Property ID | F1: Property | G1: Evidence Attachment | H1: Official Slot | I1: Run | J1: I | K1: F | L1: Y
A2: LOOCV0-P1-S0-NT-E011 | B2: LOOCV0-P1-S0-NT | C2: LOOCV0 | D2: 2025 | E2: P1 | F2: 109 Patrick Mill Circle | G2: No Table | H2: 1 | I2: 11 | J2: 565000 | K2: 550000 | L2: 518700
A3: LOOCV0-P1-S0-NT-E002 | B3: LOOCV0-P1-S0-NT | C3: LOOCV0 | D3: 2025 | E3: P1 | F3: 109 Patrick Mill Circle | G3: No Table | H3: 2 | I3: 2 | J3: 540000 | K3: 550000 | L3: 518700
A4: LOOCV0-P1-S0-NT-E003 | B4: LOOCV0-P1-S0-NT | C4: LOOCV0 | D4: 2025 | E4: P1 | F4: 109 Patrick Mill Circle | G4: No Table | H4: 3 | I4: 3 | J4: 565000 | K4: 560000 | L4: 518700
A5: LOOCV0-P1-S0-NT-E004 | B5: LOOCV0-P1-S0-NT | C5: LOOCV0 | D5: 2025 | E5: P1 | F5: 109 Patrick Mill Circle | G5: No Table | H5: 4 | I5: 4 | J5: 540000 | K5: 548000 | L5: 518700
A6: LOOCV0-P1-S0-NT-E005 | B6: LOOCV0-P1-S0-NT | C6: LOOCV0 | D6: 2025 | E6: P1 | F6: 109 Patrick Mill Circle | G6: No Table | H6: 5 | I6: 5 | J6: 555000 | K6: 550000 | L6: 518700
A7: LOOCV0-P1-S0-NT-E006 | B7: LOOCV0-P1-S0-NT | C7: LOOCV0 | D7: 2025 | E7: P1 | F7: 109 Patrick Mill Circle | G7: No Table | H7: 6 | I7: 6 | J7: 545000 | K7: 550000 | L7: 518700
A8: LOOCV0-P1-S0-NT-E012 | B8: LOOCV0-P1-S0-NT | C8: LOOCV0 | D8: 2025 | E8: P1 | F8: 109 Patrick Mill Circle | G8: No Table | H8: 7 | I8: 12 | J8: 560000 | K8: 560000 | L8: 518700
A9: LOOCV0-P1-S0-NT-E008 | B9: LOOCV0-P1-S0-NT | C9: LOOCV0 | D9: 2025 | E9: P1 | F9: 109 Patrick Mill Circle | G9: No Table | H9: 8 | I9: 8 | J9: 550000 | K9: 545000 | L9: 518700
A10: LOOCV0-P1-S0-NT-E009 | B10: LOOCV0-P1-S0-NT | C10: LOOCV0 | D10: 2025 | E10: P1 | F10: 109 Patrick Mill Circle | G10: No Table | H10: 9 | I10: 9 | J10: 560000 | K10: 555000 | L10: 518700
A11: LOOCV0-P1-S0-NT-E010 | B11: LOOCV0-P1-S0-NT | C11: LOOCV0 | D11: 2025 | E11: P1 | F11: 109 Patrick Mill Circle | G11: No Table | H11: 10 | I11: 10 | J11: 560000 | K11: 555000 | L11: 518700
A12: LOOCV0-P2-S0-NT-E001 | B12: LOOCV0-P2-S0-NT | C12: LOOCV0 | D12: 2025 | E12: P2 | F12: 265 Patrick Mill Circle | G12: No Table | H12: 1 | I12: 1 | J12: 720000 | K12: 695000 | L12: 675000
A13: LOOCV0-P2-S0-NT-E002 | B13: LOOCV0-P2-S0-NT | C13: LOOCV0 | D13: 2025 | E13: P2 | F13: 265 Patrick Mill Circle | G13: No Table | H13: 2 | I13: 2 | J13: 745000 | K13: 705000 | L13: 675000
... A461: PROSP-P1P-S0-T-E010 | B461: PROSP-P1P-S0-T | C461: PROSP | D461: 2026 | E461: P1P | F461: 144 Crosstide Circle | G461: Table | H461: 10 | I461: 10 | J461: 715000 | K461: 710000 | L461: 720000

Sheet S0 Qualified Verification
A1: S0 QUALIFIED — PREDICTIONS AND STATE CHARACTERIZATION
A2: Table results first; PROSP is separate from historical OPVAL. No Table detail and summaries are retained below.
A4: Population | B4: Representation | C4: Cells | D4: Mean APE(F) | E4: Median APE(F) | F4: Max APE(F) | G4: APE ≤ 5% | H4: Mean CV(F) | I4: Mean signed error | J4: Qualifying runs
A5: OPVAL | B5: Table | C5: =COUNTIFS($B$12:$B$39,$A5,$C$12:$C$39,$B5) -> 9 | D5: =AVERAGE(I12:I20) -> 0.012224119 | E5: =MEDIAN(I12:I20) -> 0.010551181 | F5: =MAX(I12:I20) -> 0.048103448 | G5: =COUNTIF(I12:I20,"<=0.05") -> 9 | H5: =AVERAGE(J12:J20) -> 0.007843138 | I5: =AVERAGE(K12:K20) -> 0.0047363025 | J5: =SUMIFS($E$12:$E$39,$B$12:$B$39,$A5,$C$12:$C$39,$B5) -> 90
A6: PROSP | B6: Table | C6: =COUNTIFS($B$12:$B$39,$A6,$C$12:$C$39,$B6) -> 1 | D6: =AVERAGE(I21:I21) -> 0.0079861111 | E6: =MEDIAN(I21:I21) -> 0.0079861111 | F6: =MAX(I21:I21) -> 0.0079861111 | G6: =COUNTIF(I21:I21,"<=0.05") -> 1 | H6: =AVERAGE(J21:J21) -> 0.0040584593 | I6: =AVERAGE(K21:K21) -> -0.0079861111 | J6: =SUMIFS($E$12:$E$39,$B$12:$B$39,$A6,$C$12:$C$39,$B6) -> 10
A7: LOOCV0 | B7: Table | C7: =COUNTIFS($B$12:$B$39,$A7,$C$12:$C$39,$B7) -> 9 | D7: =AVERAGE(I22:I30) -> 0.03231515 | E7: =MEDIAN(I22:I30) -> 0.026993865 | F7: =MAX(I22:I30) -> 0.069354839 | G7: =COUNTIF(I22:I30,"<=0.05") -> 6 | H7: =AVERAGE(J22:J30) -> 0.0092618297 | I7: =AVERAGE(K22:K30) -> 0.02240931 | J7: =SUMIFS($E$12:$E$39,$B$12:$B$39,$A7,$C$12:$C$39,$B7) -> 90
A8: LOOCV1 | B8: Table | C8: =COUNTIFS($B$12:$B$39,$A8,$C$12:$C$39,$B8) -> 9 | D8: =AVERAGE(I31:I39) -> 0.037168217 | E8: =MEDIAN(I31:I39) -> 0.027407407 | F8: =MAX(I31:I39) -> 0.070464623 | G8: =COUNTIF(I31:I39,"<=0.05") -> 5 | H8: =AVERAGE(J31:J39) -> 0.0068714881 | I8: =AVERAGE(K31:K39) -> 0.028084267 | J8: =SUMIFS($E$12:$E$39,$B$12:$B$39,$A8,$C$12:$C$39,$B8) -> 90
A10: TABLE PROPERTY DETAIL — OPVAL, PROSP, LOOCV0, LOOCV1
A11: Cell ID | B11: Population | C11: Representation | D11: Property ID | E11: Runs (n) | F11: Mean F | G11: SD(F) | H11: Actual Y | I11: APE(F) | J11: CV(F) | K11: Signed error | L11: Property address
A12: OPVAL-P1A-S0-T | B12: OPVAL | C12: Table | D12: P1A | E12: =COUNTIF('S0 Qualified Executions'!$B$2:$B$461,A12) -> 10 | F12: =AVERAGEIF('S0 Qualified Executions'!$B$2:$B$461,A12,'S0 Qualified Executions'!$K$2:$K$461) -> 639000 | G12: =_xlfn.STDEV.S(_xlfn._xlws.FILTER('S0 Qualified Executions'!$K$2:$K$461,'S0 Qualified Executions'!$B$2:$B$461=A12)) -> 2108.1851 | H12: =AVERAGEIF('S0 Qualified Executions'!$B$2:$B$461,A12,'S0 Qualified Executions'!$L$2:$L$461) -> 650000 | I12: =ABS(F12-H12)/H12 -> 0.016923077 | J12: =G12/F12 -> 0.0032991942 | K12: =(F12-H12)/H12 -> -0.016923077 | L12: 132 Patrick Mill Circle
A13: OPVAL-P2A-S0-T | B13: OPVAL | C13: Table | D13: P2A | E13: =COUNTIF('S0 Qualified Executions'!$B$2:$B$461,A13) -> 10 | F13: =AVERAGEIF('S0 Qualified Executions'!$B$2:$B$461,A13,'S0 Qualified Executions'!$K$2:$K$461) -> 673000 | G13: =_xlfn.STDEV.S(_xlfn._xlws.FILTER('S0 Qualified Executions'!$K$2:$K$461,'S0 Qualified Executions'!$B$2:$B$461=A13)) -> 4830.4589 | H13: =AVERAGEIF('S0 Qualified Executions'!$B$2:$B$461,A13,'S0 Qualified Executions'!$L$2:$L$461) -> 670000 | I13: =ABS(F13-H13)/H13 -> 0.0044776119 | J13: =G13/F13 -> 0.0071775021 | K13: =(F13-H13)/H13 -> 0.0044776119 | L13: 252 Seamist Court
A14: OPVAL-P3A-S0-T | B14: OPVAL | C14: Table | D14: P3A | E14: =COUNTIF('S0 Qualified Executions'!$B$2:$B$461,A14) -> 10 | F14: =AVERAGEIF('S0 Qualified Executions'!$B$2:$B$461,A14,'S0 Qualified Executions'!$K$2:$K$461) -> 781000 | G14: =_xlfn.STDEV.S(_xlfn._xlws.FILTER('S0 Qualified Executions'!$K$2:$K$461,'S0 Qualified Executions'!$B$2:$B$461=A14)) -> 5163.9778 | H14: =AVERAGEIF('S0 Qualified Executions'!$B$2:$B$461,A14,'S0 Qualified Executions'!$L$2:$L$461) -> 790000 | I14: =ABS(F14-H14)/H14 -> 0.011392405 | J14: =G14/F14 -> 0.0066120074 | K14: =(F14-H14)/H14 -> -0.011392405 | L14: 213 Seamist Court
A15: OPVAL-P4A-S0-T | B15: OPVAL | C15: Table | D15: P4A | E15: =COUNTIF('S0 Qualified Executions'!$B$2:$B$461,A15) -> 10 | F15: =AVERAGEIF('S0 Qualified Executions'!$B$2:$B$461,A15,'S0 Qualified Executions'!$K$2:$K$461) -> 748750 | G15: =_xlfn.STDEV.S(_xlfn._xlws.FILTER('S0 Qualified Executions'!$K$2:$K$461,'S0 Qualified Executions'!$B$2:$B$461=A15)) -> 6373.7744 | H15: =AVERAGEIF('S0 Qualified Executions'!$B$2:$B$461,A15,'S0 Qualified Executions'!$L$2:$L$461) -> 749900 | I15: =ABS(F15-H15)/H15 -> 0.0015335378 | J15: =G15/F15 -> 0.0085125534 | K15: =(F15-H15)/H15 -> -0.0015335378 | L15: 144 Crosscove Circle
A16: OPVAL-P5A-S0-T | B16: OPVAL | C16: Table | D16: P5A | E16: =COUNTIF('S0 Qualified Executions'!$B$2:$B$461,A16) -> 10 | F16: =AVERAGEIF('S0 Qualified Executions'!$B$2:$B$461,A16,'S0 Qualified Executions'!$K$2:$K$461) -> 641700 | G16: =_xlfn.STDEV.S(_xlfn._xlws.FILTER('S0 Qualified Executions'!$K$2:$K$461,'S0 Qualified Executions'!$B$2:$B$461=A16)) -> 4083.8435 | H16: =AVERAGEIF('S0 Qualified Executions'!$B$2:$B$461,A16,'S0 Qualified Executions'!$L$2:$L$461) -> 635000 | I16: =ABS(F16-H16)/H16 -> 0.010551181 | J16: =G16/F16 -> 0.0063641008 | K16: =(F16-H16)/H16 -> 0.010551181 | L16: 193 Crosscove Circle
A17: OPVAL-P6A-S0-T | B17: OPVAL | C17: Table | D17: P6A | E17: =COUNTIF('S0 Qualified Executions'!$B$2:$B$461,A17) -> 10 | F17: =AVERAGEIF('S0 Qualified Executions'!$B$2:$B$461,A17,'S0 Qualified Executions'!$K$2:$K$461) -> 647500 | G17: =_xlfn.STDEV.S(_xlfn._xlws.FILTER('S0 Qualified Executions'!$K$2:$K$461,'S0 Qualified Executions'!$B$2:$B$461=A17)) -> 2635.2314 | H17: =AVERAGEIF('S0 Qualified Executions'!$B$2:$B$461,A17,'S0 Qualified Executions'!$L$2:$L$461) -> 650000 | I17: =ABS(F17-H17)/H17 -> 0.0038461538 | J17: =G17/F17 -> 0.0040698554 | K17: =(F17-H17)/H17 -> -0.0038461538 | L17: 185 Crosscove Circle
A18: OPVAL-P7A-S0-T | B18: OPVAL | C18: Table | D18: P7A | E18: =COUNTIF('S0 Qualified Executions'!$B$2:$B$461,A18) -> 10 | F18: =AVERAGEIF('S0 Qualified Executions'!$B$2:$B$461,A18,'S0 Qualified Executions'!$K$2:$K$461) -> 607900 | G18: =_xlfn.STDEV.S(_xlfn._xlws.FILTER('S0 Qualified Executions'!$K$2:$K$461,'S0 Qualified Executions'!$B$2:$B$461=A18)) -> 12142.213 | H18: =AVERAGEIF('S0 Qualified Executions'!$B$2:$B$461,A18,'S0 Qualified Executions'!$L$2:$L$461) -> 580000 | I18: =ABS(F18-H18)/H18 -> 0.048103448 | J18: =G18/F18 -> 0.01997403 | K18: =(F18-H18)/H18 -> 0.048103448 | L18: 205 Stellar Court
A19: OPVAL-P8A-S0-T | B19: OPVAL | C19: Table | D19: P8A | E19: =COUNTIF('S0 Qualified Executions'!$B$2:$B$461,A19) -> 10 | F19: =AVERAGEIF('S0 Qualified Executions'!$B$2:$B$461,A19,'S0 Qualified Executions'!$K$2:$K$461) -> 725500 | G19: =_xlfn.STDEV.S(_xlfn._xlws.FILTER('S0 Qualified Executions'!$K$2:$K$461,'S0 Qualified Executions'!$B$2:$B$461=A19)) -> 5502.5247 | H19: =AVERAGEIF('S0 Qualified Executions'!$B$2:$B$461,A19,'S0 Qualified Executions'!$L$2:$L$461) -> 725000 | I19: =ABS(F19-H19)/H19 -> 0.00068965517 | J19: =G19/F19 -> 0.0075844585 | K19: =(F19-H19)/H19 -> 0.00068965517 | L19: 173 Crossroad Lakes Drive
A20: OPVAL-P9A-S0-T | B20: OPVAL | C20: Table | D20: P9A | E20: =COUNTIF('S0 Qualified Executions'!$B$2:$B$461,A20) -> 10 | F20: =AVERAGEIF('S0 Qualified Executions'!$B$2:$B$461,A20,'S0 Qualified Executions'!$K$2:$K$461) -> 607500 | G20: =_xlfn.STDEV.S(_xlfn._xlws.FILTER('S0 Qualified Executions'!$K$2:$K$461,'S0 Qualified Executions'!$B$2:$B$461=A20)) -> 4249.1829 | H20: =AVERAGEIF('S0 Qualified Executions'!$B$2:$B$461,A20,'S0 Qualified Executions'!$L$2:$L$461) -> 600000 | I20: =ABS(F20-H20)/H20 -> 0.0125 | J20: =G20/F20 -> 0.0069945398 | K20: =(F20-H20)/H20 -> 0.0125 | L20: 120 Summer Tree Court
A21: PROSP-P1P-S0-T | B21: PROSP | C21: Table | D21: P1P | E21: =COUNTIF('S0 Qualified Executions'!$B$2:$B$461,A21) -> 10 | F21: =AVERAGEIF('S0 Qualified Executions'!$B$2:$B$461,A21,'S0 Qualified Executions'!$K$2:$K$461) -> 714250 | G21: =_xlfn.STDEV.S(_xlfn._xlws.FILTER('S0 Qualified Executions'!$K$2:$K$461,'S0 Qualified Executions'!$B$2:$B$461=A21)) -> 2898.7545 | H21: =AVERAGEIF('S0 Qualified Executions'!$B$2:$B$461,A21,'S0 Qualified Executions'!$L$2:$L$461) -> 720000 | I21: =ABS(F21-H21)/H21 -> 0.0079861111 | J21: =G21/F21 -> 0.0040584593 | K21: =(F21-H21)/H21 -> -0.0079861111 | L21: 144 Crosstide Circle
A22: LOOCV0-P1-S0-T | B22: LOOCV0 | C22: Table | D22: P1 | E22: =COUNTIF('S0 Qualified Executions'!$B$2:$B$461,A22) -> 10 | F22: =AVERAGEIF('S0 Qualified Executions'!$B$2:$B$461,A22,'S0 Qualified Executions'!$K$2:$K$461) -> 545750 | G22: =_xlfn.STDEV.S(_xlfn._xlws.FILTER('S0 Qualified Executions'!$K$2:$K$461,'S0 Qualified Executions'!$B$2:$B$461=A22)) -> 2898.7545 | H22: =AVERAGEIF('S0 Qualified Executions'!$B$2:$B$461,A22,'S0 Qualified Executions'!$L$2:$L$461) -> 518700 | I22: =ABS(F22-H22)/H22 -> 0.052149605 | J22: =G22/F22 -> 0.0053115062 | K22: =(F22-H22)/H22 -> 0.052149605 | L22: 109 Patrick Mill Circle
A23: LOOCV0-P2-S0-T | B23: LOOCV0 | C23: Table | D23: P2 | E23: =COUNTIF('S0 Qualified Executions'!$B$2:$B$461,A23) -> 10 | F23: =AVERAGEIF('S0 Qualified Executions'!$B$2:$B$461,A23,'S0 Qualified Executions'!$K$2:$K$461) -> 683000 | G23: =_xlfn.STDEV.S(_xlfn._xlws.FILTER('S0 Qualified Executions'!$K$2:$K$461,'S0 Qualified Executions'!$B$2:$B$461=A23)) -> 6749.4856 | H23: =AVERAGEIF('S0 Qualified Executions'!$B$2:$B$461,A23,'S0 Qualified Executions'!$L$2:$L$461) -> 675000 | I23: =ABS(F23-H23)/H23 -> 0.011851852 | J23: =G23/F23 -> 0.0098821165 | K23: =(F23-H23)/H23 -> 0.011851852 | L23: 265 Patrick Mill Circle
... A39: LOOCV1-P9-S0-T | B39: LOOCV1 | C39: Table | D39: P9 | E39: =COUNTIF('S0 Qualified Executions'!$B$2:$B$461,A39) -> 10 | F39: =AVERAGEIF('S0 Qualified Executions'!$B$2:$B$461,A39,'S0 Qualified Executions'!$K$2:$K$461) -> 649500 | G39: =_xlfn.STDEV.S(_xlfn._xlws.FILTER('S0 Qualified Executions'!$K$2:$K$461,'S0 Qualified Executions'!$B$2:$B$461=A39)) -> 2838.2311 | H39: =AVERAGEIF('S0 Qualified Executions'!$B$2:$B$461,A39,'S0 Qualified Executions'!$L$2:$L$461) -> 610000 | I39: =ABS(F39-H39)/H39 -> 0.064754098 | J39: =G39/F39 -> 0.0043698708 | K39: =(F39-H39)/H39 -> 0.064754098 | L39: 104 Seaside Circle
A41: NO TABLE REFERENCE — OPVAL AND LOOCV0
A42: Cell ID | B42: Population | C42: Representation | D42: Property ID | E42: Runs (n) | F42: Mean F | G42: SD(F) | H42: Actual Y | I42: APE(F) | J42: CV(F) | K42: Signed error | L42: Property address
A43: OPVAL-P1A-S0-NT | B43: OPVAL | C43: No Table | D43: P1A | E43: =COUNTIF('S0 Qualified Executions'!$B$2:$B$461,A43) -> 10 | F43: =AVERAGEIF('S0 Qualified Executions'!$B$2:$B$461,A43,'S0 Qualified Executions'!$K$2:$K$461) -> 648500 | G43: =_xlfn.STDEV.S(_xlfn._xlws.FILTER('S0 Qualified Executions'!$K$2:$K$461,'S0 Qualified Executions'!$B$2:$B$461=A43)) -> 9143.9111 | H43: =AVERAGEIF('S0 Qualified Executions'!$B$2:$B$461,A43,'S0 Qualified Executions'!$L$2:$L$461) -> 650000 | I43: =ABS(F43-H43)/H43 -> 0.0023076923 | J43: =G43/F43 -> 0.014100094 | K43: =(F43-H43)/H43 -> -0.0023076923 | L43: 132 Patrick Mill Circle
A44: OPVAL-P2A-S0-NT | B44: OPVAL | C44: No Table | D44: P2A | E44: =COUNTIF('S0 Qualified Executions'!$B$2:$B$461,A44) -> 10 | F44: =AVERAGEIF('S0 Qualified Executions'!$B$2:$B$461,A44,'S0 Qualified Executions'!$K$2:$K$461) -> 685500 | G44: =_xlfn.STDEV.S(_xlfn._xlws.FILTER('S0 Qualified Executions'!$K$2:$K$461,'S0 Qualified Executions'!$B$2:$B$461=A44)) -> 9264.6281 | H44: =AVERAGEIF('S0 Qualified Executions'!$B$2:$B$461,A44,'S0 Qualified Executions'!$L$2:$L$461) -> 670000 | I44: =ABS(F44-H44)/H44 -> 0.023134328 | J44: =G44/F44 -> 0.013515139 | K44: =(F44-H44)/H44 -> 0.023134328 | L44: 252 Seamist Court
A45: OPVAL-P3A-S0-NT | B45: OPVAL | C45: No Table | D45: P3A | E45: =COUNTIF('S0 Qualified Executions'!$B$2:$B$461,A45) -> 10 | F45: =AVERAGEIF('S0 Qualified Executions'!$B$2:$B$461,A45,'S0 Qualified Executions'!$K$2:$K$461) -> 790000 | G45: =_xlfn.STDEV.S(_xlfn._xlws.FILTER('S0 Qualified Executions'!$K$2:$K$461,'S0 Qualified Executions'!$B$2:$B$461=A45)) -> 5270.4628 | H45: =AVERAGEIF('S0 Qualified Executions'!$B$2:$B$461,A45,'S0 Qualified Executions'!$L$2:$L$461) -> 790000 | I45: =ABS(F45-H45)/H45 -> 0 | J45: =G45/F45 -> 0.0066714719 | K45: =(F45-H45)/H45 -> 0 | L45: 213 Seamist Court
A46: OPVAL-P4A-S0-NT | B46: OPVAL | C46: No Table | D46: P4A | E46: =COUNTIF('S0 Qualified Executions'!$B$2:$B$461,A46) -> 10 | F46: =AVERAGEIF('S0 Qualified Executions'!$B$2:$B$461,A46,'S0 Qualified Executions'!$K$2:$K$461) -> 759000 | G46: =_xlfn.STDEV.S(_xlfn._xlws.FILTER('S0 Qualified Executions'!$K$2:$K$461,'S0 Qualified Executions'!$B$2:$B$461=A46)) -> 7745.9667 | H46: =AVERAGEIF('S0 Qualified Executions'!$B$2:$B$461,A46,'S0 Qualified Executions'!$L$2:$L$461) -> 749900 | I46: =ABS(F46-H46)/H46 -> 0.012134951 | J46: =G46/F46 -> 0.01020549 | K46: =(F46-H46)/H46 -> 0.012134951 | L46: 144 Crosscove Circle
A47: OPVAL-P5A-S0-NT | B47: OPVAL | C47: No Table | D47: P5A | E47: =COUNTIF('S0 Qualified Executions'!$B$2:$B$461,A47) -> 10 | F47: =AVERAGEIF('S0 Qualified Executions'!$B$2:$B$461,A47,'S0 Qualified Executions'!$K$2:$K$461) -> 651000 | G47: =_xlfn.STDEV.S(_xlfn._xlws.FILTER('S0 Qualified Executions'!$K$2:$K$461,'S0 Qualified Executions'!$B$2:$B$461=A47)) -> 3162.2777 | H47: =AVERAGEIF('S0 Qualified Executions'!$B$2:$B$461,A47,'S0 Qualified Executions'!$L$2:$L$461) -> 635000 | I47: =ABS(F47-H47)/H47 -> 0.02519685 | J47: =G47/F47 -> 0.0048575694 | K47: =(F47-H47)/H47 -> 0.02519685 | L47: 193 Crosscove Circle
A48: OPVAL-P6A-S0-NT | B48: OPVAL | C48: No Table | D48: P6A | E48: =COUNTIF('S0 Qualified Executions'!$B$2:$B$461,A48) -> 10 | F48: =AVERAGEIF('S0 Qualified Executions'!$B$2:$B$461,A48,'S0 Qualified Executions'!$K$2:$K$461) -> 655000 | G48: =_xlfn.STDEV.S(_xlfn._xlws.FILTER('S0 Qualified Executions'!$K$2:$K$461,'S0 Qualified Executions'!$B$2:$B$461=A48)) -> 3333.3333 | H48: =AVERAGEIF('S0 Qualified Executions'!$B$2:$B$461,A48,'S0 Qualified Executions'!$L$2:$L$461) -> 650000 | I48: =ABS(F48-H48)/H48 -> 0.0076923077 | J48: =G48/F48 -> 0.0050890585 | K48: =(F48-H48)/H48 -> 0.0076923077 | L48: 185 Crosscove Circle
A49: OPVAL-P7A-S0-NT | B49: OPVAL | C49: No Table | D49: P7A | E49: =COUNTIF('S0 Qualified Executions'!$B$2:$B$461,A49) -> 10 | F49: =AVERAGEIF('S0 Qualified Executions'!$B$2:$B$461,A49,'S0 Qualified Executions'!$K$2:$K$461) -> 604500 | G49: =_xlfn.STDEV.S(_xlfn._xlws.FILTER('S0 Qualified Executions'!$K$2:$K$461,'S0 Qualified Executions'!$B$2:$B$461=A49)) -> 12349.089 | H49: =AVERAGEIF('S0 Qualified Executions'!$B$2:$B$461,A49,'S0 Qualified Executions'!$L$2:$L$461) -> 580000 | I49: =ABS(F49-H49)/H49 -> 0.042241379 | J49: =G49/F49 -> 0.020428601 | K49: =(F49-H49)/H49 -> 0.042241379 | L49: 205 Stellar Court
A50: OPVAL-P8A-S0-NT | B50: OPVAL | C50: No Table | D50: P8A | E50: =COUNTIF('S0 Qualified Executions'!$B$2:$B$461,A50) -> 10 | F50: =AVERAGEIF('S0 Qualified Executions'!$B$2:$B$461,A50,'S0 Qualified Executions'!$K$2:$K$461) -> 723000 | G50: =_xlfn.STDEV.S(_xlfn._xlws.FILTER('S0 Qualified Executions'!$K$2:$K$461,'S0 Qualified Executions'!$B$2:$B$461=A50)) -> 14567.849 | H50: =AVERAGEIF('S0 Qualified Executions'!$B$2:$B$461,A50,'S0 Qualified Executions'!$L$2:$L$461) -> 725000 | I50: =ABS(F50-H50)/H50 -> 0.0027586207 | J50: =G50/F50 -> 0.020149169 | K50: =(F50-H50)/H50 -> -0.0027586207 | L50: 173 Crossroad Lakes Drive
A51: OPVAL-P9A-S0-NT | B51: OPVAL | C51: No Table | D51: P9A | E51: =COUNTIF('S0 Qualified Executions'!$B$2:$B$461,A51) -> 10 | F51: =AVERAGEIF('S0 Qualified Executions'!$B$2:$B$461,A51,'S0 Qualified Executions'!$K$2:$K$461) -> 605000 | G51: =_xlfn.STDEV.S(_xlfn._xlws.FILTER('S0 Qualified Executions'!$K$2:$K$461,'S0 Qualified Executions'!$B$2:$B$461=A51)) -> 8819.171 | H51: =AVERAGEIF('S0 Qualified Executions'!$B$2:$B$461,A51,'S0 Qualified Executions'!$L$2:$L$461) -> 600000 | I51: =ABS(F51-H51)/H51 -> 0.0083333333 | J51: =G51/F51 -> 0.014577142 | K51: =(F51-H51)/H51 -> 0.0083333333 | L51: 120 Summer Tree Court
A52: LOOCV0-P1-S0-NT | B52: LOOCV0 | C52: No Table | D52: P1 | E52: =COUNTIF('S0 Qualified Executions'!$B$2:$B$461,A52) -> 10 | F52: =AVERAGEIF('S0 Qualified Executions'!$B$2:$B$461,A52,'S0 Qualified Executions'!$K$2:$K$461) -> 552300 | G52: =_xlfn.STDEV.S(_xlfn._xlws.FILTER('S0 Qualified Executions'!$K$2:$K$461,'S0 Qualified Executions'!$B$2:$B$461=A52)) -> 5012.2073 | H52: =AVERAGEIF('S0 Qualified Executions'!$B$2:$B$461,A52,'S0 Qualified Executions'!$L$2:$L$461) -> 518700 | I52: =ABS(F52-H52)/H52 -> 0.064777328 | J52: =G52/F52 -> 0.0090751536 | K52: =(F52-H52)/H52 -> 0.064777328 | L52: 109 Patrick Mill Circle
A53: LOOCV0-P2-S0-NT | B53: LOOCV0 | C53: No Table | D53: P2 | E53: =COUNTIF('S0 Qualified Executions'!$B$2:$B$461,A53) -> 10 | F53: =AVERAGEIF('S0 Qualified Executions'!$B$2:$B$461,A53,'S0 Qualified Executions'!$K$2:$K$461) -> 696400 | G53: =_xlfn.STDEV.S(_xlfn._xlws.FILTER('S0 Qualified Executions'!$K$2:$K$461,'S0 Qualified Executions'!$B$2:$B$461=A53)) -> 4033.1956 | H53: =AVERAGEIF('S0 Qualified Executions'!$B$2:$B$461,A53,'S0 Qualified Executions'!$L$2:$L$461) -> 675000 | I53: =ABS(F53-H53)/H53 -> 0.031703704 | J53: =G53/F53 -> 0.0057914928 | K53: =(F53-H53)/H53 -> 0.031703704 | L53: 265 Patrick Mill Circle
A54: LOOCV0-P3-S0-NT | B54: LOOCV0 | C54: No Table | D54: P3 | E54: =COUNTIF('S0 Qualified Executions'!$B$2:$B$461,A54) -> 10 | F54: =AVERAGEIF('S0 Qualified Executions'!$B$2:$B$461,A54,'S0 Qualified Executions'!$K$2:$K$461) -> 658200 | G54: =_xlfn.STDEV.S(_xlfn._xlws.FILTER('S0 Qualified Executions'!$K$2:$K$461,'S0 Qualified Executions'!$B$2:$B$461=A54)) -> 5977.7365 | H54: =AVERAGEIF('S0 Qualified Executions'!$B$2:$B$461,A54,'S0 Qualified Executions'!$L$2:$L$461) -> 620000 | I54: =ABS(F54-H54)/H54 -> 0.061612903 | J54: =G54/F54 -> 0.0090819454 | K54: =(F54-H54)/H54 -> 0.061612903 | L54: 149 Seaside Circle
... A60: LOOCV0-P9-S0-NT | B60: LOOCV0 | C60: No Table | D60: P9 | E60: =COUNTIF('S0 Qualified Executions'!$B$2:$B$461,A60) -> 10 | F60: =AVERAGEIF('S0 Qualified Executions'!$B$2:$B$461,A60,'S0 Qualified Executions'!$K$2:$K$461) -> 658000 | G60: =_xlfn.STDEV.S(_xlfn._xlws.FILTER('S0 Qualified Executions'!$K$2:$K$461,'S0 Qualified Executions'!$B$2:$B$461=A60)) -> 10055.402 | H60: =AVERAGEIF('S0 Qualified Executions'!$B$2:$B$461,A60,'S0 Qualified Executions'!$L$2:$L$461) -> 610000 | I60: =ABS(F60-H60)/H60 -> 0.078688525 | J60: =G60/F60 -> 0.015281766 | K60: =(F60-H60)/H60 -> 0.078688525 | L60: 104 Seaside Circle
A63: NO TABLE REFERENCE SUMMARY
A64: Population | B64: Representation | C64: Cells | D64: Mean APE(F) | E64: Median APE(F) | F64: Max APE(F) | G64: APE ≤ 5% | H64: Mean CV(F) | I64: Mean signed error | J64: Qualifying runs
A65: OPVAL | B65: No Table | C65: =COUNTIFS($B$43:$B$60,$A65,$C$43:$C$60,$B65) -> 9 | D65: =AVERAGE(I43:I51) -> 0.013755496 | E65: =MEDIAN(I43:I51) -> 0.0083333333 | F65: =MAX(I43:I51) -> 0.042241379 | G65: =COUNTIF(I43:I51,"<=0.05") -> 9 | H65: =AVERAGE(J43:J51) -> 0.012177082 | I65: =AVERAGE(K43:K51) -> 0.012629649 | J65: =SUMIFS($E$43:$E$60,$B$43:$B$60,$A65,$C$43:$C$60,$B65) -> 90
...
